[2022-12-25T16:23:51.557+0000] {taskinstance.py:1087} INFO - Dependencies all met for <TaskInstance: ETL_toll_data.unzip_data manual__2022-12-25T16:18:35.697267+00:00 [queued]>
[2022-12-25T16:23:51.577+0000] {taskinstance.py:1087} INFO - Dependencies all met for <TaskInstance: ETL_toll_data.unzip_data manual__2022-12-25T16:18:35.697267+00:00 [queued]>
[2022-12-25T16:23:51.577+0000] {taskinstance.py:1283} INFO - 
--------------------------------------------------------------------------------
[2022-12-25T16:23:51.578+0000] {taskinstance.py:1284} INFO - Starting attempt 1 of 2
[2022-12-25T16:23:51.578+0000] {taskinstance.py:1285} INFO - 
--------------------------------------------------------------------------------
[2022-12-25T16:23:51.611+0000] {taskinstance.py:1304} INFO - Executing <Task(BashOperator): unzip_data> on 2022-12-25 16:18:35.697267+00:00
[2022-12-25T16:23:51.611+0000] {base_task_runner.py:129} INFO - Running on host: 8fd7e45d4638
[2022-12-25T16:23:51.612+0000] {base_task_runner.py:130} INFO - Running: ['***', 'tasks', 'run', 'ETL_toll_data', 'unzip_data', 'manual__2022-12-25T16:18:35.697267+00:00', '--job-id', '276', '--raw', '--subdir', 'DAGS_FOLDER/toll_data_etl.py', '--cfg-path', '/tmp/tmp4mg1u8em']
[2022-12-25T16:23:54.245+0000] {base_task_runner.py:116} INFO - Job 276: Subtask unzip_data /home/***/.local/lib/python3.7/site-packages/***/plugins_manager.py:258 RemovedInAirflow3Warning: This decorator is deprecated.
[2022-12-25T16:23:54.246+0000] {base_task_runner.py:116} INFO - Job 276: Subtask unzip_data 
[2022-12-25T16:23:54.246+0000] {base_task_runner.py:116} INFO - Job 276: Subtask unzip_data In previous versions, all subclasses of BaseOperator must use apply_default decorator for the `default_args` feature to work properly.
[2022-12-25T16:23:54.247+0000] {base_task_runner.py:116} INFO - Job 276: Subtask unzip_data 
[2022-12-25T16:23:54.247+0000] {base_task_runner.py:116} INFO - Job 276: Subtask unzip_data In current version, it is optional. The decorator is applied automatically using the metaclass.
[2022-12-25T16:23:54.247+0000] {base_task_runner.py:116} INFO - Job 276: Subtask unzip_data 
[2022-12-25T16:23:54.624+0000] {base_task_runner.py:116} INFO - Job 276: Subtask unzip_data [[34m2022-12-25 16:23:54,623[0m] {[34mdagbag.py:[0m538} INFO[0m - Filling up the DagBag from /opt/***/dags/toll_data_etl.py[0m
[2022-12-25T16:23:55.634+0000] {base_task_runner.py:116} INFO - Job 276: Subtask unzip_data [[34m2022-12-25 16:23:55,634[0m] {[34mtask_command.py:[0m389} INFO[0m - Running <TaskInstance: ETL_toll_data.unzip_data manual__2022-12-25T16:18:35.697267+00:00 [running]> on host 8fd7e45d4638[0m
[2022-12-25T16:23:55.805+0000] {taskinstance.py:1513} INFO - Exporting the following env vars:
AIRFLOW_CTX_DAG_EMAIL=bala@yopmail.com
AIRFLOW_CTX_DAG_OWNER=bala
AIRFLOW_CTX_DAG_ID=ETL_toll_data
AIRFLOW_CTX_TASK_ID=unzip_data
AIRFLOW_CTX_EXECUTION_DATE=2022-12-25T16:18:35.697267+00:00
AIRFLOW_CTX_TRY_NUMBER=1
AIRFLOW_CTX_DAG_RUN_ID=manual__2022-12-25T16:18:35.697267+00:00
[2022-12-25T16:23:55.809+0000] {subprocess.py:63} INFO - Tmp dir root location: 
 /tmp
[2022-12-25T16:23:55.809+0000] {subprocess.py:75} INFO - Running command: ['/bin/bash', '-c', 'sudo wget https://cf-courses-data.s3.us.cloud-object-storage.appdomain.cloud/IBM-DB0250EN-SkillsNetwork/labs/Final%20Assignment/tolldata.tgz &&  tar zxvf tolldata.tgz -C ./data']
[2022-12-25T16:23:55.822+0000] {subprocess.py:86} INFO - Output:
[2022-12-25T16:23:55.844+0000] {subprocess.py:93} INFO - --2022-12-25 16:23:55--  https://cf-courses-data.s3.us.cloud-object-storage.appdomain.cloud/IBM-DB0250EN-SkillsNetwork/labs/Final%20Assignment/tolldata.tgz
[2022-12-25T16:23:56.240+0000] {subprocess.py:93} INFO - Resolving cf-courses-data.s3.us.cloud-object-storage.appdomain.cloud (cf-courses-data.s3.us.cloud-object-storage.appdomain.cloud)... 169.45.118.108
[2022-12-25T16:23:56.547+0000] {subprocess.py:93} INFO - Connecting to cf-courses-data.s3.us.cloud-object-storage.appdomain.cloud (cf-courses-data.s3.us.cloud-object-storage.appdomain.cloud)|169.45.118.108|:443... connected.
[2022-12-25T16:23:56.719+0000] {local_task_job.py:207} WARNING - Recorded pid 1211 does not match the current pid 1212
[2022-12-25T16:23:56.722+0000] {process_utils.py:133} INFO - Sending Signals.SIGTERM to group 1212. PIDs of all processes in the group: [1223, 1224, 1225, 1212]
[2022-12-25T16:23:56.722+0000] {process_utils.py:84} INFO - Sending the signal Signals.SIGTERM to group 1212
[2022-12-25T16:23:56.723+0000] {taskinstance.py:1483} ERROR - Received SIGTERM. Terminating subprocesses.
[2022-12-25T16:23:56.723+0000] {subprocess.py:104} INFO - Sending SIGTERM signal to process group
[2022-12-25T16:23:56.746+0000] {taskinstance.py:1772} ERROR - Task failed with exception
Traceback (most recent call last):
  File "/home/airflow/.local/lib/python3.7/site-packages/airflow/operators/bash.py", line 191, in execute
    cwd=self.cwd,
  File "/home/airflow/.local/lib/python3.7/site-packages/airflow/hooks/subprocess.py", line 91, in run_command
    for raw_line in iter(self.sub_process.stdout.readline, b""):
  File "/home/airflow/.local/lib/python3.7/site-packages/airflow/models/taskinstance.py", line 1485, in signal_handler
    raise AirflowException("Task received SIGTERM signal")
airflow.exceptions.AirflowException: Task received SIGTERM signal
[2022-12-25T16:23:56.754+0000] {taskinstance.py:1327} INFO - Marking task as UP_FOR_RETRY. dag_id=ETL_toll_data, task_id=unzip_data, execution_date=20221225T161835, start_date=20221225T162351, end_date=20221225T162356
[2022-12-25T16:23:56.795+0000] {logging_mixin.py:137} WARNING - /home/***/.local/lib/python3.7/site-packages/***/utils/email.py:120 RemovedInAirflow3Warning: Fetching SMTP credentials from configuration variables will be deprecated in a future release. Please set credentials using a connection instead.
[2022-12-25T16:23:56.796+0000] {configuration.py:635} WARNING - section/key [smtp/smtp_user] not found in config
[2022-12-25T16:23:56.796+0000] {email.py:229} INFO - Email alerting: attempt 1
[2022-12-25T16:23:56.810+0000] {configuration.py:635} WARNING - section/key [smtp/smtp_user] not found in config
[2022-12-25T16:23:56.810+0000] {email.py:229} INFO - Email alerting: attempt 1
[2022-12-25T16:23:56.811+0000] {taskinstance.py:1835} ERROR - Failed to send email to: ['bala@yopmail.com']
Traceback (most recent call last):
  File "/home/airflow/.local/lib/python3.7/site-packages/airflow/models/taskinstance.py", line 1378, in _run_raw_task
    self._execute_task_with_callbacks(context, test_mode)
  File "/home/airflow/.local/lib/python3.7/site-packages/airflow/models/taskinstance.py", line 1524, in _execute_task_with_callbacks
    result = self._execute_task(context, task_orig)
  File "/home/airflow/.local/lib/python3.7/site-packages/airflow/models/taskinstance.py", line 1585, in _execute_task
    result = execute_callable(context=context)
  File "/home/airflow/.local/lib/python3.7/site-packages/airflow/operators/bash.py", line 191, in execute
    cwd=self.cwd,
  File "/home/airflow/.local/lib/python3.7/site-packages/airflow/hooks/subprocess.py", line 91, in run_command
    for raw_line in iter(self.sub_process.stdout.readline, b""):
  File "/home/airflow/.local/lib/python3.7/site-packages/airflow/models/taskinstance.py", line 1485, in signal_handler
    raise AirflowException("Task received SIGTERM signal")
airflow.exceptions.AirflowException: Task received SIGTERM signal

During handling of the above exception, another exception occurred:

Traceback (most recent call last):
  File "/home/airflow/.local/lib/python3.7/site-packages/airflow/models/taskinstance.py", line 2235, in email_alert
    send_email(task.email, subject, html_content)
  File "/home/airflow/.local/lib/python3.7/site-packages/airflow/utils/email.py", line 72, in send_email
    **kwargs,
  File "/home/airflow/.local/lib/python3.7/site-packages/airflow/utils/email.py", line 120, in send_email_smtp
    send_mime_email(e_from=mail_from, e_to=recipients, mime_msg=msg, conn_id=conn_id, dryrun=dryrun)
  File "/home/airflow/.local/lib/python3.7/site-packages/airflow/utils/email.py", line 231, in send_mime_email
    smtp_conn = _get_smtp_connection(smtp_host, smtp_port, smtp_timeout, smtp_ssl)
  File "/home/airflow/.local/lib/python3.7/site-packages/airflow/utils/email.py", line 265, in _get_smtp_connection
    else smtplib.SMTP(host=host, port=port, timeout=timeout)
  File "/usr/local/lib/python3.7/smtplib.py", line 251, in __init__
    (code, msg) = self.connect(host, port)
  File "/usr/local/lib/python3.7/smtplib.py", line 336, in connect
    self.sock = self._get_socket(host, port, self.timeout)
  File "/usr/local/lib/python3.7/smtplib.py", line 307, in _get_socket
    self.source_address)
  File "/usr/local/lib/python3.7/socket.py", line 728, in create_connection
    raise err
  File "/usr/local/lib/python3.7/socket.py", line 716, in create_connection
    sock.connect(sa)
OSError: [Errno 99] Cannot assign requested address

During handling of the above exception, another exception occurred:

Traceback (most recent call last):
  File "/home/airflow/.local/lib/python3.7/site-packages/airflow/models/taskinstance.py", line 1833, in handle_failure
    self.email_alert(error, task)
  File "/home/airflow/.local/lib/python3.7/site-packages/airflow/models/taskinstance.py", line 2237, in email_alert
    send_email(task.email, subject, html_content_err)
  File "/home/airflow/.local/lib/python3.7/site-packages/airflow/utils/email.py", line 72, in send_email
    **kwargs,
  File "/home/airflow/.local/lib/python3.7/site-packages/airflow/utils/email.py", line 120, in send_email_smtp
    send_mime_email(e_from=mail_from, e_to=recipients, mime_msg=msg, conn_id=conn_id, dryrun=dryrun)
  File "/home/airflow/.local/lib/python3.7/site-packages/airflow/utils/email.py", line 231, in send_mime_email
    smtp_conn = _get_smtp_connection(smtp_host, smtp_port, smtp_timeout, smtp_ssl)
  File "/home/airflow/.local/lib/python3.7/site-packages/airflow/utils/email.py", line 265, in _get_smtp_connection
    else smtplib.SMTP(host=host, port=port, timeout=timeout)
  File "/usr/local/lib/python3.7/smtplib.py", line 251, in __init__
    (code, msg) = self.connect(host, port)
  File "/usr/local/lib/python3.7/smtplib.py", line 336, in connect
    self.sock = self._get_socket(host, port, self.timeout)
  File "/usr/local/lib/python3.7/smtplib.py", line 307, in _get_socket
    self.source_address)
  File "/usr/local/lib/python3.7/socket.py", line 728, in create_connection
    raise err
  File "/usr/local/lib/python3.7/socket.py", line 716, in create_connection
    sock.connect(sa)
OSError: [Errno 99] Cannot assign requested address
[2022-12-25T16:23:56.863+0000] {base_task_runner.py:116} INFO - Job 276: Subtask unzip_data Traceback (most recent call last):
[2022-12-25T16:23:56.863+0000] {base_task_runner.py:116} INFO - Job 276: Subtask unzip_data   File "/home/***/.local/bin/***", line 8, in <module>
[2022-12-25T16:23:56.864+0000] {base_task_runner.py:116} INFO - Job 276: Subtask unzip_data     sys.exit(main())
[2022-12-25T16:23:56.864+0000] {base_task_runner.py:116} INFO - Job 276: Subtask unzip_data   File "/home/***/.local/lib/python3.7/site-packages/***/__main__.py", line 39, in main
[2022-12-25T16:23:56.864+0000] {base_task_runner.py:116} INFO - Job 276: Subtask unzip_data     args.func(args)
[2022-12-25T16:23:56.864+0000] {base_task_runner.py:116} INFO - Job 276: Subtask unzip_data   File "/home/***/.local/lib/python3.7/site-packages/***/cli/cli_parser.py", line 52, in command
[2022-12-25T16:23:56.865+0000] {base_task_runner.py:116} INFO - Job 276: Subtask unzip_data     return func(*args, **kwargs)
[2022-12-25T16:23:56.865+0000] {base_task_runner.py:116} INFO - Job 276: Subtask unzip_data   File "/home/***/.local/lib/python3.7/site-packages/***/utils/cli.py", line 108, in wrapper
[2022-12-25T16:23:56.865+0000] {base_task_runner.py:116} INFO - Job 276: Subtask unzip_data     return f(*args, **kwargs)
[2022-12-25T16:23:56.865+0000] {base_task_runner.py:116} INFO - Job 276: Subtask unzip_data   File "/home/***/.local/lib/python3.7/site-packages/***/cli/commands/task_command.py", line 396, in task_run
[2022-12-25T16:23:56.866+0000] {base_task_runner.py:116} INFO - Job 276: Subtask unzip_data     _run_task_by_selected_method(args, dag, ti)
[2022-12-25T16:23:56.866+0000] {base_task_runner.py:116} INFO - Job 276: Subtask unzip_data   File "/home/***/.local/lib/python3.7/site-packages/***/cli/commands/task_command.py", line 195, in _run_task_by_selected_method
[2022-12-25T16:23:56.866+0000] {base_task_runner.py:116} INFO - Job 276: Subtask unzip_data     _run_raw_task(args, ti)
[2022-12-25T16:23:56.867+0000] {base_task_runner.py:116} INFO - Job 276: Subtask unzip_data   File "/home/***/.local/lib/python3.7/site-packages/***/cli/commands/task_command.py", line 272, in _run_raw_task
[2022-12-25T16:23:56.867+0000] {base_task_runner.py:116} INFO - Job 276: Subtask unzip_data     pool=args.pool,
[2022-12-25T16:23:56.867+0000] {base_task_runner.py:116} INFO - Job 276: Subtask unzip_data   File "/home/***/.local/lib/python3.7/site-packages/***/utils/session.py", line 75, in wrapper
[2022-12-25T16:23:56.868+0000] {base_task_runner.py:116} INFO - Job 276: Subtask unzip_data     return func(*args, session=session, **kwargs)
[2022-12-25T16:23:56.868+0000] {base_task_runner.py:116} INFO - Job 276: Subtask unzip_data   File "/home/***/.local/lib/python3.7/site-packages/***/models/taskinstance.py", line 1378, in _run_raw_task
[2022-12-25T16:23:56.868+0000] {base_task_runner.py:116} INFO - Job 276: Subtask unzip_data     self._execute_task_with_callbacks(context, test_mode)
[2022-12-25T16:23:56.869+0000] {base_task_runner.py:116} INFO - Job 276: Subtask unzip_data   File "/home/***/.local/lib/python3.7/site-packages/***/models/taskinstance.py", line 1524, in _execute_task_with_callbacks
[2022-12-25T16:23:56.869+0000] {base_task_runner.py:116} INFO - Job 276: Subtask unzip_data     result = self._execute_task(context, task_orig)
[2022-12-25T16:23:56.869+0000] {base_task_runner.py:116} INFO - Job 276: Subtask unzip_data   File "/home/***/.local/lib/python3.7/site-packages/***/models/taskinstance.py", line 1585, in _execute_task
[2022-12-25T16:23:56.870+0000] {base_task_runner.py:116} INFO - Job 276: Subtask unzip_data     result = execute_callable(context=context)
[2022-12-25T16:23:56.870+0000] {base_task_runner.py:116} INFO - Job 276: Subtask unzip_data   File "/home/***/.local/lib/python3.7/site-packages/***/operators/bash.py", line 191, in execute
[2022-12-25T16:23:56.871+0000] {base_task_runner.py:116} INFO - Job 276: Subtask unzip_data     cwd=self.cwd,
[2022-12-25T16:23:56.871+0000] {base_task_runner.py:116} INFO - Job 276: Subtask unzip_data   File "/home/***/.local/lib/python3.7/site-packages/***/hooks/subprocess.py", line 91, in run_command
[2022-12-25T16:23:56.871+0000] {base_task_runner.py:116} INFO - Job 276: Subtask unzip_data     for raw_line in iter(self.sub_process.stdout.readline, b""):
[2022-12-25T16:23:56.871+0000] {base_task_runner.py:116} INFO - Job 276: Subtask unzip_data   File "/home/***/.local/lib/python3.7/site-packages/***/models/taskinstance.py", line 1485, in signal_handler
[2022-12-25T16:23:56.872+0000] {base_task_runner.py:116} INFO - Job 276: Subtask unzip_data     raise AirflowException("Task received SIGTERM signal")
[2022-12-25T16:23:56.872+0000] {base_task_runner.py:116} INFO - Job 276: Subtask unzip_data ***.exceptions.AirflowException: Task received SIGTERM signal
[2022-12-25T16:23:57.108+0000] {process_utils.py:79} INFO - Process psutil.Process(pid=1223, status='terminated', started='16:23:55') (1223) terminated with exit code None
[2022-12-25T16:23:57.109+0000] {process_utils.py:79} INFO - Process psutil.Process(pid=1224, status='terminated', started='16:23:55') (1224) terminated with exit code None
[2022-12-25T16:23:57.110+0000] {process_utils.py:79} INFO - Process psutil.Process(pid=1225, status='terminated', started='16:23:55') (1225) terminated with exit code None
[2022-12-25T16:23:57.323+0000] {process_utils.py:79} INFO - Process psutil.Process(pid=1212, status='terminated', exitcode=1, started='16:23:51') (1212) terminated with exit code 1
