[2022-12-25T16:18:37.657+0000] {taskinstance.py:1087} INFO - Dependencies all met for <TaskInstance: ETL_toll_data.test_impersonated_user manual__2022-12-25T16:18:35.697267+00:00 [queued]>
[2022-12-25T16:18:37.678+0000] {taskinstance.py:1087} INFO - Dependencies all met for <TaskInstance: ETL_toll_data.test_impersonated_user manual__2022-12-25T16:18:35.697267+00:00 [queued]>
[2022-12-25T16:18:37.678+0000] {taskinstance.py:1283} INFO - 
--------------------------------------------------------------------------------
[2022-12-25T16:18:37.679+0000] {taskinstance.py:1284} INFO - Starting attempt 1 of 2
[2022-12-25T16:18:37.679+0000] {taskinstance.py:1285} INFO - 
--------------------------------------------------------------------------------
[2022-12-25T16:18:37.712+0000] {taskinstance.py:1304} INFO - Executing <Task(BashOperator): test_impersonated_user> on 2022-12-25 16:18:35.697267+00:00
[2022-12-25T16:18:37.713+0000] {base_task_runner.py:129} INFO - Running on host: 8fd7e45d4638
[2022-12-25T16:18:37.713+0000] {base_task_runner.py:130} INFO - Running: ['***', 'tasks', 'run', 'ETL_toll_data', 'test_impersonated_user', 'manual__2022-12-25T16:18:35.697267+00:00', '--job-id', '272', '--raw', '--subdir', 'DAGS_FOLDER/toll_data_etl.py', '--cfg-path', '/tmp/tmpht7d82im']
[2022-12-25T16:18:40.643+0000] {base_task_runner.py:116} INFO - Job 272: Subtask test_impersonated_user /home/***/.local/lib/python3.7/site-packages/***/plugins_manager.py:258 RemovedInAirflow3Warning: This decorator is deprecated.
[2022-12-25T16:18:40.644+0000] {base_task_runner.py:116} INFO - Job 272: Subtask test_impersonated_user 
[2022-12-25T16:18:40.645+0000] {base_task_runner.py:116} INFO - Job 272: Subtask test_impersonated_user In previous versions, all subclasses of BaseOperator must use apply_default decorator for the `default_args` feature to work properly.
[2022-12-25T16:18:40.645+0000] {base_task_runner.py:116} INFO - Job 272: Subtask test_impersonated_user 
[2022-12-25T16:18:40.645+0000] {base_task_runner.py:116} INFO - Job 272: Subtask test_impersonated_user In current version, it is optional. The decorator is applied automatically using the metaclass.
[2022-12-25T16:18:40.646+0000] {base_task_runner.py:116} INFO - Job 272: Subtask test_impersonated_user 
[2022-12-25T16:18:41.208+0000] {base_task_runner.py:116} INFO - Job 272: Subtask test_impersonated_user [[34m2022-12-25 16:18:41,208[0m] {[34mdagbag.py:[0m538} INFO[0m - Filling up the DagBag from /opt/***/dags/toll_data_etl.py[0m
[2022-12-25T16:18:42.476+0000] {base_task_runner.py:116} INFO - Job 272: Subtask test_impersonated_user [[34m2022-12-25 16:18:42,475[0m] {[34mtask_command.py:[0m389} INFO[0m - Running <TaskInstance: ETL_toll_data.test_impersonated_user manual__2022-12-25T16:18:35.697267+00:00 [running]> on host 8fd7e45d4638[0m
[2022-12-25T16:18:42.798+0000] {local_task_job.py:207} WARNING - Recorded pid 941 does not match the current pid 942
[2022-12-25T16:18:42.802+0000] {process_utils.py:133} INFO - Sending Signals.SIGTERM to group 942. PIDs of all processes in the group: [942]
[2022-12-25T16:18:42.802+0000] {process_utils.py:84} INFO - Sending the signal Signals.SIGTERM to group 942
[2022-12-25T16:18:42.870+0000] {taskinstance.py:1483} ERROR - Received SIGTERM. Terminating subprocesses.
[2022-12-25T16:18:42.871+0000] {subprocess.py:104} INFO - Sending SIGTERM signal to process group
[2022-12-25T16:18:42.903+0000] {taskinstance.py:1772} ERROR - Task failed with exception
Traceback (most recent call last):
  File "/home/airflow/.local/lib/python3.7/site-packages/airflow/models/taskinstance.py", line 1378, in _run_raw_task
    self._execute_task_with_callbacks(context, test_mode)
  File "/home/airflow/.local/lib/python3.7/site-packages/airflow/models/taskinstance.py", line 1500, in _execute_task_with_callbacks
    RenderedTaskInstanceFields.write(rtif)
  File "/home/airflow/.local/lib/python3.7/site-packages/airflow/utils/session.py", line 75, in wrapper
    return func(*args, session=session, **kwargs)
  File "/usr/local/lib/python3.7/contextlib.py", line 119, in __exit__
    next(self.gen)
  File "/home/airflow/.local/lib/python3.7/site-packages/airflow/utils/session.py", line 36, in create_session
    session.commit()
  File "/home/airflow/.local/lib/python3.7/site-packages/sqlalchemy/orm/session.py", line 1451, in commit
    self._transaction.commit(_to_root=self.future)
  File "/home/airflow/.local/lib/python3.7/site-packages/sqlalchemy/orm/session.py", line 836, in commit
    trans.commit()
  File "/home/airflow/.local/lib/python3.7/site-packages/sqlalchemy/engine/base.py", line 2459, in commit
    self._do_commit()
  File "/home/airflow/.local/lib/python3.7/site-packages/sqlalchemy/engine/base.py", line 2649, in _do_commit
    self._connection_commit_impl()
  File "/home/airflow/.local/lib/python3.7/site-packages/sqlalchemy/engine/base.py", line 2620, in _connection_commit_impl
    self.connection._commit_impl()
  File "/home/airflow/.local/lib/python3.7/site-packages/sqlalchemy/engine/base.py", line 1091, in _commit_impl
    self._handle_dbapi_exception(e, None, None, None, None)
  File "/home/airflow/.local/lib/python3.7/site-packages/sqlalchemy/engine/base.py", line 2128, in _handle_dbapi_exception
    util.raise_(exc_info[1], with_traceback=exc_info[2])
  File "/home/airflow/.local/lib/python3.7/site-packages/sqlalchemy/util/compat.py", line 210, in raise_
    raise exception
  File "/home/airflow/.local/lib/python3.7/site-packages/sqlalchemy/engine/base.py", line 1089, in _commit_impl
    self.engine.dialect.do_commit(self.connection)
  File "/home/airflow/.local/lib/python3.7/site-packages/sqlalchemy/engine/default.py", line 686, in do_commit
    dbapi_connection.commit()
  File "/home/airflow/.local/lib/python3.7/site-packages/airflow/models/taskinstance.py", line 1485, in signal_handler
    raise AirflowException("Task received SIGTERM signal")
airflow.exceptions.AirflowException: Task received SIGTERM signal
[2022-12-25T16:18:42.963+0000] {taskinstance.py:1327} INFO - Marking task as UP_FOR_RETRY. dag_id=ETL_toll_data, task_id=test_impersonated_user, execution_date=20221225T161835, start_date=20221225T161837, end_date=20221225T161842
[2022-12-25T16:18:43.005+0000] {logging_mixin.py:137} WARNING - /home/***/.local/lib/python3.7/site-packages/***/utils/email.py:120 RemovedInAirflow3Warning: Fetching SMTP credentials from configuration variables will be deprecated in a future release. Please set credentials using a connection instead.
[2022-12-25T16:18:43.006+0000] {configuration.py:635} WARNING - section/key [smtp/smtp_user] not found in config
[2022-12-25T16:18:43.006+0000] {email.py:229} INFO - Email alerting: attempt 1
[2022-12-25T16:18:43.019+0000] {configuration.py:635} WARNING - section/key [smtp/smtp_user] not found in config
[2022-12-25T16:18:43.019+0000] {email.py:229} INFO - Email alerting: attempt 1
[2022-12-25T16:18:43.020+0000] {taskinstance.py:1835} ERROR - Failed to send email to: ['bala@yopmail.com']
Traceback (most recent call last):
  File "/home/airflow/.local/lib/python3.7/site-packages/airflow/models/taskinstance.py", line 1378, in _run_raw_task
    self._execute_task_with_callbacks(context, test_mode)
  File "/home/airflow/.local/lib/python3.7/site-packages/airflow/models/taskinstance.py", line 1500, in _execute_task_with_callbacks
    RenderedTaskInstanceFields.write(rtif)
  File "/home/airflow/.local/lib/python3.7/site-packages/airflow/utils/session.py", line 75, in wrapper
    return func(*args, session=session, **kwargs)
  File "/usr/local/lib/python3.7/contextlib.py", line 119, in __exit__
    next(self.gen)
  File "/home/airflow/.local/lib/python3.7/site-packages/airflow/utils/session.py", line 36, in create_session
    session.commit()
  File "/home/airflow/.local/lib/python3.7/site-packages/sqlalchemy/orm/session.py", line 1451, in commit
    self._transaction.commit(_to_root=self.future)
  File "/home/airflow/.local/lib/python3.7/site-packages/sqlalchemy/orm/session.py", line 836, in commit
    trans.commit()
  File "/home/airflow/.local/lib/python3.7/site-packages/sqlalchemy/engine/base.py", line 2459, in commit
    self._do_commit()
  File "/home/airflow/.local/lib/python3.7/site-packages/sqlalchemy/engine/base.py", line 2649, in _do_commit
    self._connection_commit_impl()
  File "/home/airflow/.local/lib/python3.7/site-packages/sqlalchemy/engine/base.py", line 2620, in _connection_commit_impl
    self.connection._commit_impl()
  File "/home/airflow/.local/lib/python3.7/site-packages/sqlalchemy/engine/base.py", line 1091, in _commit_impl
    self._handle_dbapi_exception(e, None, None, None, None)
  File "/home/airflow/.local/lib/python3.7/site-packages/sqlalchemy/engine/base.py", line 2128, in _handle_dbapi_exception
    util.raise_(exc_info[1], with_traceback=exc_info[2])
  File "/home/airflow/.local/lib/python3.7/site-packages/sqlalchemy/util/compat.py", line 210, in raise_
    raise exception
  File "/home/airflow/.local/lib/python3.7/site-packages/sqlalchemy/engine/base.py", line 1089, in _commit_impl
    self.engine.dialect.do_commit(self.connection)
  File "/home/airflow/.local/lib/python3.7/site-packages/sqlalchemy/engine/default.py", line 686, in do_commit
    dbapi_connection.commit()
  File "/home/airflow/.local/lib/python3.7/site-packages/airflow/models/taskinstance.py", line 1485, in signal_handler
    raise AirflowException("Task received SIGTERM signal")
airflow.exceptions.AirflowException: Task received SIGTERM signal

During handling of the above exception, another exception occurred:

Traceback (most recent call last):
  File "/home/airflow/.local/lib/python3.7/site-packages/airflow/models/taskinstance.py", line 2235, in email_alert
    send_email(task.email, subject, html_content)
  File "/home/airflow/.local/lib/python3.7/site-packages/airflow/utils/email.py", line 72, in send_email
    **kwargs,
  File "/home/airflow/.local/lib/python3.7/site-packages/airflow/utils/email.py", line 120, in send_email_smtp
    send_mime_email(e_from=mail_from, e_to=recipients, mime_msg=msg, conn_id=conn_id, dryrun=dryrun)
  File "/home/airflow/.local/lib/python3.7/site-packages/airflow/utils/email.py", line 231, in send_mime_email
    smtp_conn = _get_smtp_connection(smtp_host, smtp_port, smtp_timeout, smtp_ssl)
  File "/home/airflow/.local/lib/python3.7/site-packages/airflow/utils/email.py", line 265, in _get_smtp_connection
    else smtplib.SMTP(host=host, port=port, timeout=timeout)
  File "/usr/local/lib/python3.7/smtplib.py", line 251, in __init__
    (code, msg) = self.connect(host, port)
  File "/usr/local/lib/python3.7/smtplib.py", line 336, in connect
    self.sock = self._get_socket(host, port, self.timeout)
  File "/usr/local/lib/python3.7/smtplib.py", line 307, in _get_socket
    self.source_address)
  File "/usr/local/lib/python3.7/socket.py", line 728, in create_connection
    raise err
  File "/usr/local/lib/python3.7/socket.py", line 716, in create_connection
    sock.connect(sa)
OSError: [Errno 99] Cannot assign requested address

During handling of the above exception, another exception occurred:

Traceback (most recent call last):
  File "/home/airflow/.local/lib/python3.7/site-packages/airflow/models/taskinstance.py", line 1833, in handle_failure
    self.email_alert(error, task)
  File "/home/airflow/.local/lib/python3.7/site-packages/airflow/models/taskinstance.py", line 2237, in email_alert
    send_email(task.email, subject, html_content_err)
  File "/home/airflow/.local/lib/python3.7/site-packages/airflow/utils/email.py", line 72, in send_email
    **kwargs,
  File "/home/airflow/.local/lib/python3.7/site-packages/airflow/utils/email.py", line 120, in send_email_smtp
    send_mime_email(e_from=mail_from, e_to=recipients, mime_msg=msg, conn_id=conn_id, dryrun=dryrun)
  File "/home/airflow/.local/lib/python3.7/site-packages/airflow/utils/email.py", line 231, in send_mime_email
    smtp_conn = _get_smtp_connection(smtp_host, smtp_port, smtp_timeout, smtp_ssl)
  File "/home/airflow/.local/lib/python3.7/site-packages/airflow/utils/email.py", line 265, in _get_smtp_connection
    else smtplib.SMTP(host=host, port=port, timeout=timeout)
  File "/usr/local/lib/python3.7/smtplib.py", line 251, in __init__
    (code, msg) = self.connect(host, port)
  File "/usr/local/lib/python3.7/smtplib.py", line 336, in connect
    self.sock = self._get_socket(host, port, self.timeout)
  File "/usr/local/lib/python3.7/smtplib.py", line 307, in _get_socket
    self.source_address)
  File "/usr/local/lib/python3.7/socket.py", line 728, in create_connection
    raise err
  File "/usr/local/lib/python3.7/socket.py", line 716, in create_connection
    sock.connect(sa)
OSError: [Errno 99] Cannot assign requested address
[2022-12-25T16:18:43.052+0000] {base_task_runner.py:116} INFO - Job 272: Subtask test_impersonated_user Traceback (most recent call last):
[2022-12-25T16:18:43.053+0000] {base_task_runner.py:116} INFO - Job 272: Subtask test_impersonated_user   File "/home/***/.local/bin/***", line 8, in <module>
[2022-12-25T16:18:43.053+0000] {base_task_runner.py:116} INFO - Job 272: Subtask test_impersonated_user     sys.exit(main())
[2022-12-25T16:18:43.054+0000] {base_task_runner.py:116} INFO - Job 272: Subtask test_impersonated_user   File "/home/***/.local/lib/python3.7/site-packages/***/__main__.py", line 39, in main
[2022-12-25T16:18:43.054+0000] {base_task_runner.py:116} INFO - Job 272: Subtask test_impersonated_user     args.func(args)
[2022-12-25T16:18:43.054+0000] {base_task_runner.py:116} INFO - Job 272: Subtask test_impersonated_user   File "/home/***/.local/lib/python3.7/site-packages/***/cli/cli_parser.py", line 52, in command
[2022-12-25T16:18:43.054+0000] {base_task_runner.py:116} INFO - Job 272: Subtask test_impersonated_user     return func(*args, **kwargs)
[2022-12-25T16:18:43.055+0000] {base_task_runner.py:116} INFO - Job 272: Subtask test_impersonated_user   File "/home/***/.local/lib/python3.7/site-packages/***/utils/cli.py", line 108, in wrapper
[2022-12-25T16:18:43.055+0000] {base_task_runner.py:116} INFO - Job 272: Subtask test_impersonated_user     return f(*args, **kwargs)
[2022-12-25T16:18:43.055+0000] {base_task_runner.py:116} INFO - Job 272: Subtask test_impersonated_user   File "/home/***/.local/lib/python3.7/site-packages/***/cli/commands/task_command.py", line 396, in task_run
[2022-12-25T16:18:43.056+0000] {base_task_runner.py:116} INFO - Job 272: Subtask test_impersonated_user     _run_task_by_selected_method(args, dag, ti)
[2022-12-25T16:18:43.056+0000] {base_task_runner.py:116} INFO - Job 272: Subtask test_impersonated_user   File "/home/***/.local/lib/python3.7/site-packages/***/cli/commands/task_command.py", line 195, in _run_task_by_selected_method
[2022-12-25T16:18:43.057+0000] {base_task_runner.py:116} INFO - Job 272: Subtask test_impersonated_user     _run_raw_task(args, ti)
[2022-12-25T16:18:43.057+0000] {base_task_runner.py:116} INFO - Job 272: Subtask test_impersonated_user   File "/home/***/.local/lib/python3.7/site-packages/***/cli/commands/task_command.py", line 272, in _run_raw_task
[2022-12-25T16:18:43.057+0000] {base_task_runner.py:116} INFO - Job 272: Subtask test_impersonated_user     pool=args.pool,
[2022-12-25T16:18:43.057+0000] {base_task_runner.py:116} INFO - Job 272: Subtask test_impersonated_user   File "/home/***/.local/lib/python3.7/site-packages/***/utils/session.py", line 75, in wrapper
[2022-12-25T16:18:43.058+0000] {base_task_runner.py:116} INFO - Job 272: Subtask test_impersonated_user     return func(*args, session=session, **kwargs)
[2022-12-25T16:18:43.058+0000] {base_task_runner.py:116} INFO - Job 272: Subtask test_impersonated_user   File "/home/***/.local/lib/python3.7/site-packages/***/models/taskinstance.py", line 1378, in _run_raw_task
[2022-12-25T16:18:43.058+0000] {base_task_runner.py:116} INFO - Job 272: Subtask test_impersonated_user     self._execute_task_with_callbacks(context, test_mode)
[2022-12-25T16:18:43.059+0000] {base_task_runner.py:116} INFO - Job 272: Subtask test_impersonated_user   File "/home/***/.local/lib/python3.7/site-packages/***/models/taskinstance.py", line 1500, in _execute_task_with_callbacks
[2022-12-25T16:18:43.059+0000] {base_task_runner.py:116} INFO - Job 272: Subtask test_impersonated_user     RenderedTaskInstanceFields.write(rtif)
[2022-12-25T16:18:43.059+0000] {base_task_runner.py:116} INFO - Job 272: Subtask test_impersonated_user   File "/home/***/.local/lib/python3.7/site-packages/***/utils/session.py", line 75, in wrapper
[2022-12-25T16:18:43.059+0000] {base_task_runner.py:116} INFO - Job 272: Subtask test_impersonated_user     return func(*args, session=session, **kwargs)
[2022-12-25T16:18:43.060+0000] {base_task_runner.py:116} INFO - Job 272: Subtask test_impersonated_user   File "/usr/local/lib/python3.7/contextlib.py", line 119, in __exit__
[2022-12-25T16:18:43.060+0000] {base_task_runner.py:116} INFO - Job 272: Subtask test_impersonated_user     next(self.gen)
[2022-12-25T16:18:43.060+0000] {base_task_runner.py:116} INFO - Job 272: Subtask test_impersonated_user   File "/home/***/.local/lib/python3.7/site-packages/***/utils/session.py", line 36, in create_session
[2022-12-25T16:18:43.061+0000] {base_task_runner.py:116} INFO - Job 272: Subtask test_impersonated_user     session.commit()
[2022-12-25T16:18:43.061+0000] {base_task_runner.py:116} INFO - Job 272: Subtask test_impersonated_user   File "/home/***/.local/lib/python3.7/site-packages/sqlalchemy/orm/session.py", line 1451, in commit
[2022-12-25T16:18:43.061+0000] {base_task_runner.py:116} INFO - Job 272: Subtask test_impersonated_user     self._transaction.commit(_to_root=self.future)
[2022-12-25T16:18:43.061+0000] {base_task_runner.py:116} INFO - Job 272: Subtask test_impersonated_user   File "/home/***/.local/lib/python3.7/site-packages/sqlalchemy/orm/session.py", line 836, in commit
[2022-12-25T16:18:43.062+0000] {base_task_runner.py:116} INFO - Job 272: Subtask test_impersonated_user     trans.commit()
[2022-12-25T16:18:43.062+0000] {base_task_runner.py:116} INFO - Job 272: Subtask test_impersonated_user   File "/home/***/.local/lib/python3.7/site-packages/sqlalchemy/engine/base.py", line 2459, in commit
[2022-12-25T16:18:43.062+0000] {base_task_runner.py:116} INFO - Job 272: Subtask test_impersonated_user     self._do_commit()
[2022-12-25T16:18:43.063+0000] {base_task_runner.py:116} INFO - Job 272: Subtask test_impersonated_user   File "/home/***/.local/lib/python3.7/site-packages/sqlalchemy/engine/base.py", line 2649, in _do_commit
[2022-12-25T16:18:43.063+0000] {base_task_runner.py:116} INFO - Job 272: Subtask test_impersonated_user     self._connection_commit_impl()
[2022-12-25T16:18:43.063+0000] {base_task_runner.py:116} INFO - Job 272: Subtask test_impersonated_user   File "/home/***/.local/lib/python3.7/site-packages/sqlalchemy/engine/base.py", line 2620, in _connection_commit_impl
[2022-12-25T16:18:43.063+0000] {base_task_runner.py:116} INFO - Job 272: Subtask test_impersonated_user     self.connection._commit_impl()
[2022-12-25T16:18:43.064+0000] {base_task_runner.py:116} INFO - Job 272: Subtask test_impersonated_user   File "/home/***/.local/lib/python3.7/site-packages/sqlalchemy/engine/base.py", line 1091, in _commit_impl
[2022-12-25T16:18:43.064+0000] {base_task_runner.py:116} INFO - Job 272: Subtask test_impersonated_user     self._handle_dbapi_exception(e, None, None, None, None)
[2022-12-25T16:18:43.064+0000] {base_task_runner.py:116} INFO - Job 272: Subtask test_impersonated_user   File "/home/***/.local/lib/python3.7/site-packages/sqlalchemy/engine/base.py", line 2128, in _handle_dbapi_exception
[2022-12-25T16:18:43.065+0000] {base_task_runner.py:116} INFO - Job 272: Subtask test_impersonated_user     util.raise_(exc_info[1], with_traceback=exc_info[2])
[2022-12-25T16:18:43.065+0000] {base_task_runner.py:116} INFO - Job 272: Subtask test_impersonated_user   File "/home/***/.local/lib/python3.7/site-packages/sqlalchemy/util/compat.py", line 210, in raise_
[2022-12-25T16:18:43.065+0000] {base_task_runner.py:116} INFO - Job 272: Subtask test_impersonated_user     raise exception
[2022-12-25T16:18:43.066+0000] {base_task_runner.py:116} INFO - Job 272: Subtask test_impersonated_user   File "/home/***/.local/lib/python3.7/site-packages/sqlalchemy/engine/base.py", line 1089, in _commit_impl
[2022-12-25T16:18:43.066+0000] {base_task_runner.py:116} INFO - Job 272: Subtask test_impersonated_user     self.engine.dialect.do_commit(self.connection)
[2022-12-25T16:18:43.066+0000] {base_task_runner.py:116} INFO - Job 272: Subtask test_impersonated_user   File "/home/***/.local/lib/python3.7/site-packages/sqlalchemy/engine/default.py", line 686, in do_commit
[2022-12-25T16:18:43.067+0000] {base_task_runner.py:116} INFO - Job 272: Subtask test_impersonated_user     dbapi_connection.commit()
[2022-12-25T16:18:43.067+0000] {base_task_runner.py:116} INFO - Job 272: Subtask test_impersonated_user   File "/home/***/.local/lib/python3.7/site-packages/***/models/taskinstance.py", line 1485, in signal_handler
[2022-12-25T16:18:43.067+0000] {base_task_runner.py:116} INFO - Job 272: Subtask test_impersonated_user     raise AirflowException("Task received SIGTERM signal")
[2022-12-25T16:18:43.068+0000] {base_task_runner.py:116} INFO - Job 272: Subtask test_impersonated_user ***.exceptions.AirflowException: Task received SIGTERM signal
[2022-12-25T16:18:43.465+0000] {process_utils.py:79} INFO - Process psutil.Process(pid=942, status='terminated', exitcode=1, started='16:18:37') (942) terminated with exit code 1
