[2022-12-25T13:33:14.096+0000] {taskinstance.py:1087} INFO - Dependencies all met for <TaskInstance: ETL_toll_data.unzip_data manual__2022-12-25T13:28:28.984562+00:00 [queued]>
[2022-12-25T13:33:14.204+0000] {taskinstance.py:1087} INFO - Dependencies all met for <TaskInstance: ETL_toll_data.unzip_data manual__2022-12-25T13:28:28.984562+00:00 [queued]>
[2022-12-25T13:33:14.204+0000] {taskinstance.py:1283} INFO - 
--------------------------------------------------------------------------------
[2022-12-25T13:33:14.204+0000] {taskinstance.py:1284} INFO - Starting attempt 2 of 3
[2022-12-25T13:33:14.204+0000] {taskinstance.py:1285} INFO - 
--------------------------------------------------------------------------------
[2022-12-25T13:33:14.441+0000] {taskinstance.py:1304} INFO - Executing <Task(BashOperator): unzip_data> on 2022-12-25 13:28:28.984562+00:00
[2022-12-25T13:33:14.448+0000] {standard_task_runner.py:55} INFO - Started process 130 to run task
[2022-12-25T13:33:14.451+0000] {standard_task_runner.py:82} INFO - Running: ['***', 'tasks', 'run', 'ETL_toll_data', 'unzip_data', 'manual__2022-12-25T13:28:28.984562+00:00', '--job-id', '242', '--raw', '--subdir', 'DAGS_FOLDER/toll_data_etl.py', '--cfg-path', '/tmp/tmp3vix0e_6']
[2022-12-25T13:33:14.452+0000] {standard_task_runner.py:83} INFO - Job 242: Subtask unzip_data
[2022-12-25T13:33:15.019+0000] {task_command.py:389} INFO - Running <TaskInstance: ETL_toll_data.unzip_data manual__2022-12-25T13:28:28.984562+00:00 [running]> on host c3abbdcdc080
[2022-12-25T13:33:15.637+0000] {taskinstance.py:1513} INFO - Exporting the following env vars:
AIRFLOW_CTX_DAG_EMAIL=bala@yopmail.com
AIRFLOW_CTX_DAG_OWNER=bala
AIRFLOW_CTX_DAG_ID=ETL_toll_data
AIRFLOW_CTX_TASK_ID=unzip_data
AIRFLOW_CTX_EXECUTION_DATE=2022-12-25T13:28:28.984562+00:00
AIRFLOW_CTX_TRY_NUMBER=2
AIRFLOW_CTX_DAG_RUN_ID=manual__2022-12-25T13:28:28.984562+00:00
[2022-12-25T13:33:15.638+0000] {subprocess.py:63} INFO - Tmp dir root location: 
 /tmp
[2022-12-25T13:33:15.638+0000] {subprocess.py:75} INFO - Running command: ['/bin/bash', '-c', 'wget https://cf-courses-data.s3.us.cloud-object-storage.appdomain.cloud/IBM-DB0250EN-SkillsNetwork/labs/Final%20Assignment/tolldata.tgz &&  tar zxvf tolldata.tgz -C ./data']
[2022-12-25T13:33:15.660+0000] {subprocess.py:86} INFO - Output:
[2022-12-25T13:33:15.775+0000] {subprocess.py:93} INFO - --2022-12-25 13:33:15--  https://cf-courses-data.s3.us.cloud-object-storage.appdomain.cloud/IBM-DB0250EN-SkillsNetwork/labs/Final%20Assignment/tolldata.tgz
[2022-12-25T13:33:16.126+0000] {subprocess.py:93} INFO - Resolving cf-courses-data.s3.us.cloud-object-storage.appdomain.cloud (cf-courses-data.s3.us.cloud-object-storage.appdomain.cloud)... 169.45.118.108
[2022-12-25T13:33:16.433+0000] {subprocess.py:93} INFO - Connecting to cf-courses-data.s3.us.cloud-object-storage.appdomain.cloud (cf-courses-data.s3.us.cloud-object-storage.appdomain.cloud)|169.45.118.108|:443... connected.
[2022-12-25T13:33:17.460+0000] {subprocess.py:93} INFO - HTTP request sent, awaiting response... 200 OK
[2022-12-25T13:33:17.461+0000] {subprocess.py:93} INFO - Length: 528994 (517K) [application/x-tar]
[2022-12-25T13:33:17.462+0000] {subprocess.py:93} INFO - Saving to: ‘tolldata.tgz’
[2022-12-25T13:33:17.462+0000] {subprocess.py:93} INFO - 
[2022-12-25T13:33:18.073+0000] {subprocess.py:93} INFO -      0K .......... .......... .......... .......... ..........  9% 81.7K 6s
[2022-12-25T13:33:18.301+0000] {subprocess.py:93} INFO -     50K .......... .......... .......... .......... .......... 19%  219K 3s
[2022-12-25T13:33:18.308+0000] {subprocess.py:93} INFO -    100K .......... .......... .......... .......... .......... 29% 6.60M 2s
[2022-12-25T13:33:18.316+0000] {subprocess.py:93} INFO -    150K .......... .......... .......... .......... .......... 38% 6.85M 1s
[2022-12-25T13:33:18.544+0000] {subprocess.py:93} INFO -    200K .......... .......... .......... .......... .......... 48%  219K 1s
[2022-12-25T13:33:18.551+0000] {subprocess.py:93} INFO -    250K .......... .......... .......... .......... .......... 58% 6.88M 1s
[2022-12-25T13:33:18.558+0000] {subprocess.py:93} INFO -    300K .......... .......... .......... .......... .......... 67% 6.83M 1s
[2022-12-25T13:33:18.569+0000] {subprocess.py:93} INFO -    350K .......... .......... .......... .......... .......... 77% 7.06M 0s
[2022-12-25T13:33:18.576+0000] {subprocess.py:93} INFO -    400K .......... .......... .......... .......... .......... 87% 4.62M 0s
[2022-12-25T13:33:18.802+0000] {subprocess.py:93} INFO -    450K .......... .......... .......... .......... .......... 96%  220K 0s
[2022-12-25T13:33:18.804+0000] {subprocess.py:93} INFO -    500K .......... ......                                     100% 8.64M=1.3s
[2022-12-25T13:33:18.804+0000] {subprocess.py:93} INFO - 
[2022-12-25T13:33:18.805+0000] {subprocess.py:93} INFO - 2022-12-25 13:33:18 (385 KB/s) - ‘tolldata.tgz’ saved [528994/528994]
[2022-12-25T13:33:18.805+0000] {subprocess.py:93} INFO - 
[2022-12-25T13:33:18.881+0000] {subprocess.py:93} INFO - tar: data: Cannot open: No such file or directory
[2022-12-25T13:33:18.882+0000] {subprocess.py:93} INFO - tar: Error is not recoverable: exiting now
[2022-12-25T13:33:18.882+0000] {subprocess.py:97} INFO - Command exited with return code 2
[2022-12-25T13:33:18.906+0000] {taskinstance.py:1772} ERROR - Task failed with exception
Traceback (most recent call last):
  File "/home/airflow/.local/lib/python3.7/site-packages/airflow/operators/bash.py", line 197, in execute
    f"Bash command failed. The command returned a non-zero exit code {result.exit_code}."
airflow.exceptions.AirflowException: Bash command failed. The command returned a non-zero exit code 2.
[2022-12-25T13:33:18.913+0000] {taskinstance.py:1327} INFO - Marking task as UP_FOR_RETRY. dag_id=ETL_toll_data, task_id=unzip_data, execution_date=20221225T132828, start_date=20221225T133314, end_date=20221225T133318
[2022-12-25T13:33:18.940+0000] {warnings.py:110} WARNING - /home/***/.local/lib/python3.7/site-packages/***/utils/email.py:120: RemovedInAirflow3Warning: Fetching SMTP credentials from configuration variables will be deprecated in a future release. Please set credentials using a connection instead.
  send_mime_email(e_from=mail_from, e_to=recipients, mime_msg=msg, conn_id=conn_id, dryrun=dryrun)

[2022-12-25T13:33:18.940+0000] {configuration.py:635} WARNING - section/key [smtp/smtp_user] not found in config
[2022-12-25T13:33:18.940+0000] {email.py:229} INFO - Email alerting: attempt 1
[2022-12-25T13:33:18.947+0000] {configuration.py:635} WARNING - section/key [smtp/smtp_user] not found in config
[2022-12-25T13:33:18.947+0000] {email.py:229} INFO - Email alerting: attempt 1
[2022-12-25T13:33:18.947+0000] {taskinstance.py:1835} ERROR - Failed to send email to: ['bala@yopmail.com']
Traceback (most recent call last):
  File "/home/airflow/.local/lib/python3.7/site-packages/airflow/models/taskinstance.py", line 1378, in _run_raw_task
    self._execute_task_with_callbacks(context, test_mode)
  File "/home/airflow/.local/lib/python3.7/site-packages/airflow/models/taskinstance.py", line 1524, in _execute_task_with_callbacks
    result = self._execute_task(context, task_orig)
  File "/home/airflow/.local/lib/python3.7/site-packages/airflow/models/taskinstance.py", line 1585, in _execute_task
    result = execute_callable(context=context)
  File "/home/airflow/.local/lib/python3.7/site-packages/airflow/operators/bash.py", line 197, in execute
    f"Bash command failed. The command returned a non-zero exit code {result.exit_code}."
airflow.exceptions.AirflowException: Bash command failed. The command returned a non-zero exit code 2.

During handling of the above exception, another exception occurred:

Traceback (most recent call last):
  File "/home/airflow/.local/lib/python3.7/site-packages/airflow/models/taskinstance.py", line 2235, in email_alert
    send_email(task.email, subject, html_content)
  File "/home/airflow/.local/lib/python3.7/site-packages/airflow/utils/email.py", line 72, in send_email
    **kwargs,
  File "/home/airflow/.local/lib/python3.7/site-packages/airflow/utils/email.py", line 120, in send_email_smtp
    send_mime_email(e_from=mail_from, e_to=recipients, mime_msg=msg, conn_id=conn_id, dryrun=dryrun)
  File "/home/airflow/.local/lib/python3.7/site-packages/airflow/utils/email.py", line 231, in send_mime_email
    smtp_conn = _get_smtp_connection(smtp_host, smtp_port, smtp_timeout, smtp_ssl)
  File "/home/airflow/.local/lib/python3.7/site-packages/airflow/utils/email.py", line 265, in _get_smtp_connection
    else smtplib.SMTP(host=host, port=port, timeout=timeout)
  File "/usr/local/lib/python3.7/smtplib.py", line 251, in __init__
    (code, msg) = self.connect(host, port)
  File "/usr/local/lib/python3.7/smtplib.py", line 336, in connect
    self.sock = self._get_socket(host, port, self.timeout)
  File "/usr/local/lib/python3.7/smtplib.py", line 307, in _get_socket
    self.source_address)
  File "/usr/local/lib/python3.7/socket.py", line 728, in create_connection
    raise err
  File "/usr/local/lib/python3.7/socket.py", line 716, in create_connection
    sock.connect(sa)
OSError: [Errno 99] Cannot assign requested address

During handling of the above exception, another exception occurred:

Traceback (most recent call last):
  File "/home/airflow/.local/lib/python3.7/site-packages/airflow/models/taskinstance.py", line 1833, in handle_failure
    self.email_alert(error, task)
  File "/home/airflow/.local/lib/python3.7/site-packages/airflow/models/taskinstance.py", line 2237, in email_alert
    send_email(task.email, subject, html_content_err)
  File "/home/airflow/.local/lib/python3.7/site-packages/airflow/utils/email.py", line 72, in send_email
    **kwargs,
  File "/home/airflow/.local/lib/python3.7/site-packages/airflow/utils/email.py", line 120, in send_email_smtp
    send_mime_email(e_from=mail_from, e_to=recipients, mime_msg=msg, conn_id=conn_id, dryrun=dryrun)
  File "/home/airflow/.local/lib/python3.7/site-packages/airflow/utils/email.py", line 231, in send_mime_email
    smtp_conn = _get_smtp_connection(smtp_host, smtp_port, smtp_timeout, smtp_ssl)
  File "/home/airflow/.local/lib/python3.7/site-packages/airflow/utils/email.py", line 265, in _get_smtp_connection
    else smtplib.SMTP(host=host, port=port, timeout=timeout)
  File "/usr/local/lib/python3.7/smtplib.py", line 251, in __init__
    (code, msg) = self.connect(host, port)
  File "/usr/local/lib/python3.7/smtplib.py", line 336, in connect
    self.sock = self._get_socket(host, port, self.timeout)
  File "/usr/local/lib/python3.7/smtplib.py", line 307, in _get_socket
    self.source_address)
  File "/usr/local/lib/python3.7/socket.py", line 728, in create_connection
    raise err
  File "/usr/local/lib/python3.7/socket.py", line 716, in create_connection
    sock.connect(sa)
OSError: [Errno 99] Cannot assign requested address
[2022-12-25T13:33:18.974+0000] {standard_task_runner.py:105} ERROR - Failed to execute job 242 for task unzip_data (Bash command failed. The command returned a non-zero exit code 2.; 130)
[2022-12-25T13:33:19.004+0000] {local_task_job.py:159} INFO - Task exited with return code 1
[2022-12-25T13:33:19.041+0000] {taskinstance.py:2582} INFO - 0 downstream tasks scheduled from follow-on schedule check
