[2022-12-25T14:04:21.879+0000] {taskinstance.py:1087} INFO - Dependencies all met for <TaskInstance: ETL_toll_data.unzip_data manual__2022-12-25T13:58:44.853296+00:00 [queued]>
[2022-12-25T14:04:21.888+0000] {taskinstance.py:1087} INFO - Dependencies all met for <TaskInstance: ETL_toll_data.unzip_data manual__2022-12-25T13:58:44.853296+00:00 [queued]>
[2022-12-25T14:04:21.888+0000] {taskinstance.py:1283} INFO - 
--------------------------------------------------------------------------------
[2022-12-25T14:04:21.888+0000] {taskinstance.py:1284} INFO - Starting attempt 2 of 2
[2022-12-25T14:04:21.888+0000] {taskinstance.py:1285} INFO - 
--------------------------------------------------------------------------------
[2022-12-25T14:04:21.912+0000] {taskinstance.py:1304} INFO - Executing <Task(BashOperator): unzip_data> on 2022-12-25 13:58:44.853296+00:00
[2022-12-25T14:04:21.917+0000] {standard_task_runner.py:55} INFO - Started process 323 to run task
[2022-12-25T14:04:21.920+0000] {standard_task_runner.py:82} INFO - Running: ['***', 'tasks', 'run', 'ETL_toll_data', 'unzip_data', 'manual__2022-12-25T13:58:44.853296+00:00', '--job-id', '252', '--raw', '--subdir', 'DAGS_FOLDER/toll_data_etl.py', '--cfg-path', '/tmp/tmp9wd4ex7z']
[2022-12-25T14:04:21.921+0000] {standard_task_runner.py:83} INFO - Job 252: Subtask unzip_data
[2022-12-25T14:04:21.983+0000] {task_command.py:389} INFO - Running <TaskInstance: ETL_toll_data.unzip_data manual__2022-12-25T13:58:44.853296+00:00 [running]> on host c3abbdcdc080
[2022-12-25T14:04:22.059+0000] {taskinstance.py:1513} INFO - Exporting the following env vars:
AIRFLOW_CTX_DAG_EMAIL=bala@yopmail.com
AIRFLOW_CTX_DAG_OWNER=bala
AIRFLOW_CTX_DAG_ID=ETL_toll_data
AIRFLOW_CTX_TASK_ID=unzip_data
AIRFLOW_CTX_EXECUTION_DATE=2022-12-25T13:58:44.853296+00:00
AIRFLOW_CTX_TRY_NUMBER=2
AIRFLOW_CTX_DAG_RUN_ID=manual__2022-12-25T13:58:44.853296+00:00
[2022-12-25T14:04:22.060+0000] {subprocess.py:63} INFO - Tmp dir root location: 
 /tmp
[2022-12-25T14:04:22.060+0000] {subprocess.py:75} INFO - Running command: ['/bin/bash', '-c', 'sudo wget https://cf-courses-data.s3.us.cloud-object-storage.appdomain.cloud/IBM-DB0250EN-SkillsNetwork/labs/Final%20Assignment/tolldata.tgz &&  tar zxvf tolldata.tgz -C ./data']
[2022-12-25T14:04:22.072+0000] {subprocess.py:86} INFO - Output:
[2022-12-25T14:04:22.081+0000] {subprocess.py:93} INFO - --2022-12-25 14:04:22--  https://cf-courses-data.s3.us.cloud-object-storage.appdomain.cloud/IBM-DB0250EN-SkillsNetwork/labs/Final%20Assignment/tolldata.tgz
[2022-12-25T14:04:23.596+0000] {subprocess.py:93} INFO - Resolving cf-courses-data.s3.us.cloud-object-storage.appdomain.cloud (cf-courses-data.s3.us.cloud-object-storage.appdomain.cloud)... 169.45.118.108
[2022-12-25T14:04:39.263+0000] {subprocess.py:93} INFO - Connecting to cf-courses-data.s3.us.cloud-object-storage.appdomain.cloud (cf-courses-data.s3.us.cloud-object-storage.appdomain.cloud)|169.45.118.108|:443... connected.
[2022-12-25T14:04:40.186+0000] {subprocess.py:93} INFO - HTTP request sent, awaiting response... 200 OK
[2022-12-25T14:04:40.186+0000] {subprocess.py:93} INFO - Length: 528994 (517K) [application/x-tar]
[2022-12-25T14:04:40.186+0000] {subprocess.py:93} INFO - Saving to: ‘tolldata.tgz’
[2022-12-25T14:04:40.186+0000] {subprocess.py:93} INFO - 
[2022-12-25T14:04:40.799+0000] {subprocess.py:93} INFO -      0K .......... .......... .......... .......... ..........  9% 81.6K 6s
[2022-12-25T14:04:40.802+0000] {subprocess.py:93} INFO -     50K .......... .......... .......... .......... .......... 19% 15.2M 3s
[2022-12-25T14:04:41.109+0000] {subprocess.py:93} INFO -    100K .......... .......... .......... .......... .......... 29%  163K 2s
[2022-12-25T14:04:41.618+0000] {subprocess.py:93} INFO -    150K .......... .......... .......... .......... .......... 38% 98.2K 2s
[2022-12-25T14:04:41.621+0000] {subprocess.py:93} INFO -    200K .......... .......... .......... .......... .......... 48% 18.0M 2s
[2022-12-25T14:04:41.621+0000] {subprocess.py:93} INFO -    250K .......... .......... .......... .......... .......... 58% 66.5M 1s
[2022-12-25T14:04:41.622+0000] {subprocess.py:93} INFO -    300K .......... .......... .......... .......... .......... 67% 81.4M 1s
[2022-12-25T14:04:41.623+0000] {subprocess.py:93} INFO -    350K .......... .......... .......... .......... .......... 77% 65.1M 0s
[2022-12-25T14:04:41.929+0000] {subprocess.py:93} INFO -    400K .......... .......... .......... .......... .......... 87%  163K 0s
[2022-12-25T14:04:42.993+0000] {subprocess.py:93} INFO -    450K .......... .......... .......... .......... .......... 96% 47.0K 0s
[2022-12-25T14:04:42.997+0000] {subprocess.py:93} INFO -    500K .......... ......                                     100% 5.05M=2.8s
[2022-12-25T14:04:42.998+0000] {subprocess.py:93} INFO - 
[2022-12-25T14:04:42.998+0000] {subprocess.py:93} INFO - 2022-12-25 14:04:42 (184 KB/s) - ‘tolldata.tgz’ saved [528994/528994]
[2022-12-25T14:04:42.999+0000] {subprocess.py:93} INFO - 
[2022-12-25T14:04:43.018+0000] {subprocess.py:93} INFO - tar: data: Cannot open: No such file or directory
[2022-12-25T14:04:43.019+0000] {subprocess.py:93} INFO - tar: Error is not recoverable: exiting now
[2022-12-25T14:04:43.021+0000] {subprocess.py:97} INFO - Command exited with return code 2
[2022-12-25T14:04:43.060+0000] {taskinstance.py:1772} ERROR - Task failed with exception
Traceback (most recent call last):
  File "/home/airflow/.local/lib/python3.7/site-packages/airflow/operators/bash.py", line 197, in execute
    f"Bash command failed. The command returned a non-zero exit code {result.exit_code}."
airflow.exceptions.AirflowException: Bash command failed. The command returned a non-zero exit code 2.
[2022-12-25T14:04:43.070+0000] {taskinstance.py:1327} INFO - Marking task as FAILED. dag_id=ETL_toll_data, task_id=unzip_data, execution_date=20221225T135844, start_date=20221225T140421, end_date=20221225T140443
[2022-12-25T14:04:43.112+0000] {warnings.py:110} WARNING - /home/***/.local/lib/python3.7/site-packages/***/utils/email.py:120: RemovedInAirflow3Warning: Fetching SMTP credentials from configuration variables will be deprecated in a future release. Please set credentials using a connection instead.
  send_mime_email(e_from=mail_from, e_to=recipients, mime_msg=msg, conn_id=conn_id, dryrun=dryrun)

[2022-12-25T14:04:43.112+0000] {configuration.py:635} WARNING - section/key [smtp/smtp_user] not found in config
[2022-12-25T14:04:43.112+0000] {email.py:229} INFO - Email alerting: attempt 1
[2022-12-25T14:04:43.118+0000] {configuration.py:635} WARNING - section/key [smtp/smtp_user] not found in config
[2022-12-25T14:04:43.119+0000] {email.py:229} INFO - Email alerting: attempt 1
[2022-12-25T14:04:43.119+0000] {taskinstance.py:1835} ERROR - Failed to send email to: ['bala@yopmail.com']
Traceback (most recent call last):
  File "/home/airflow/.local/lib/python3.7/site-packages/airflow/models/taskinstance.py", line 1378, in _run_raw_task
    self._execute_task_with_callbacks(context, test_mode)
  File "/home/airflow/.local/lib/python3.7/site-packages/airflow/models/taskinstance.py", line 1524, in _execute_task_with_callbacks
    result = self._execute_task(context, task_orig)
  File "/home/airflow/.local/lib/python3.7/site-packages/airflow/models/taskinstance.py", line 1585, in _execute_task
    result = execute_callable(context=context)
  File "/home/airflow/.local/lib/python3.7/site-packages/airflow/operators/bash.py", line 197, in execute
    f"Bash command failed. The command returned a non-zero exit code {result.exit_code}."
airflow.exceptions.AirflowException: Bash command failed. The command returned a non-zero exit code 2.

During handling of the above exception, another exception occurred:

Traceback (most recent call last):
  File "/home/airflow/.local/lib/python3.7/site-packages/airflow/models/taskinstance.py", line 2235, in email_alert
    send_email(task.email, subject, html_content)
  File "/home/airflow/.local/lib/python3.7/site-packages/airflow/utils/email.py", line 72, in send_email
    **kwargs,
  File "/home/airflow/.local/lib/python3.7/site-packages/airflow/utils/email.py", line 120, in send_email_smtp
    send_mime_email(e_from=mail_from, e_to=recipients, mime_msg=msg, conn_id=conn_id, dryrun=dryrun)
  File "/home/airflow/.local/lib/python3.7/site-packages/airflow/utils/email.py", line 231, in send_mime_email
    smtp_conn = _get_smtp_connection(smtp_host, smtp_port, smtp_timeout, smtp_ssl)
  File "/home/airflow/.local/lib/python3.7/site-packages/airflow/utils/email.py", line 265, in _get_smtp_connection
    else smtplib.SMTP(host=host, port=port, timeout=timeout)
  File "/usr/local/lib/python3.7/smtplib.py", line 251, in __init__
    (code, msg) = self.connect(host, port)
  File "/usr/local/lib/python3.7/smtplib.py", line 336, in connect
    self.sock = self._get_socket(host, port, self.timeout)
  File "/usr/local/lib/python3.7/smtplib.py", line 307, in _get_socket
    self.source_address)
  File "/usr/local/lib/python3.7/socket.py", line 728, in create_connection
    raise err
  File "/usr/local/lib/python3.7/socket.py", line 716, in create_connection
    sock.connect(sa)
OSError: [Errno 99] Cannot assign requested address

During handling of the above exception, another exception occurred:

Traceback (most recent call last):
  File "/home/airflow/.local/lib/python3.7/site-packages/airflow/models/taskinstance.py", line 1833, in handle_failure
    self.email_alert(error, task)
  File "/home/airflow/.local/lib/python3.7/site-packages/airflow/models/taskinstance.py", line 2237, in email_alert
    send_email(task.email, subject, html_content_err)
  File "/home/airflow/.local/lib/python3.7/site-packages/airflow/utils/email.py", line 72, in send_email
    **kwargs,
  File "/home/airflow/.local/lib/python3.7/site-packages/airflow/utils/email.py", line 120, in send_email_smtp
    send_mime_email(e_from=mail_from, e_to=recipients, mime_msg=msg, conn_id=conn_id, dryrun=dryrun)
  File "/home/airflow/.local/lib/python3.7/site-packages/airflow/utils/email.py", line 231, in send_mime_email
    smtp_conn = _get_smtp_connection(smtp_host, smtp_port, smtp_timeout, smtp_ssl)
  File "/home/airflow/.local/lib/python3.7/site-packages/airflow/utils/email.py", line 265, in _get_smtp_connection
    else smtplib.SMTP(host=host, port=port, timeout=timeout)
  File "/usr/local/lib/python3.7/smtplib.py", line 251, in __init__
    (code, msg) = self.connect(host, port)
  File "/usr/local/lib/python3.7/smtplib.py", line 336, in connect
    self.sock = self._get_socket(host, port, self.timeout)
  File "/usr/local/lib/python3.7/smtplib.py", line 307, in _get_socket
    self.source_address)
  File "/usr/local/lib/python3.7/socket.py", line 728, in create_connection
    raise err
  File "/usr/local/lib/python3.7/socket.py", line 716, in create_connection
    sock.connect(sa)
OSError: [Errno 99] Cannot assign requested address
[2022-12-25T14:04:43.148+0000] {standard_task_runner.py:105} ERROR - Failed to execute job 252 for task unzip_data (Bash command failed. The command returned a non-zero exit code 2.; 323)
[2022-12-25T14:04:43.213+0000] {local_task_job.py:159} INFO - Task exited with return code 1
[2022-12-25T14:04:43.268+0000] {taskinstance.py:2582} INFO - 0 downstream tasks scheduled from follow-on schedule check
